<?xml version="1.0" encoding="utf-8"?>
<!-- This URDF was automatically created by SolidWorks to URDF Exporter! Originally created by Stephen Brawner (brawner@gmail.com) 
     Commit Version: 1.6.0-4-g7f85cfe  Build Version: 1.6.7995.38578
     For more information, please see http://wiki.ros.org/sw_urdf_exporter -->
<robot
  name="hybrid_3f">
  <link
    name="base_link">
    <inertial>
      <origin
        xyz="0.0010253 -0.0029533 0.044672"
        rpy="0 0 0" />
      <mass
        value="0.14997" />
      <inertia
        ixx="0.00013563"
        ixy="2.6239E-06"
        ixz="-1.5605E-06"
        iyy="0.00013108"
        iyz="7.5771E-07"
        izz="0.00025029" />
    </inertial>
    <visual>
      <origin
        xyz="0 0 0"
        rpy="0 0 0" />
      <geometry>
        <mesh
          filename="../meshes/base_link.STL" />
      </geometry>
      <material
        name="">
        <color
          rgba="1 1 1 1" />
      </material>
    </visual>
    <collision>
      <origin
        xyz="0 0 0"
        rpy="0 0 0" />
      <geometry>
        <mesh
          filename="../meshes/base_link.STL" />
      </geometry>
    </collision>
  </link>
  <link
    name="thumb_bsae_link">
    <inertial>
      <origin
        xyz="-3.5757E-09 -0.00047962 0.010876"
        rpy="0 0 0" />
      <mass
        value="0.0091031" />
      <inertia
        ixx="9.4294E-07"
        ixy="9.2304E-13"
        ixz="3.6917E-13"
        iyy="8.5939E-07"
        iyz="-8.4941E-09"
        izz="3.1234E-07" />
    </inertial>
    <visual>
      <origin
        xyz="0 0 0"
        rpy="0 0 0" />
      <geometry>
        <mesh
          filename="../meshes/thumb_bsae_link.STL" />
      </geometry>
      <material
        name="">
        <color
          rgba="1 1 1 1" />
      </material>
    </visual>
    <collision>
      <origin
        xyz="0 0 0"
        rpy="0 0 0" />
      <geometry>
        <mesh
          filename="../meshes/thumb_bsae_link.STL" />
      </geometry>
    </collision>
  </link>
  <joint
    name="thumb_bsae_joint"
    type="revolute">
    <origin
      xyz="0 -0.0355 0.0923"
      rpy="0 0 0" />
    <parent
      link="base_link" />
    <child
      link="thumb_bsae_link" />
    <axis
      xyz="0 0 1" />
    <limit
      lower="-1.57"
      upper="1.57"
      effort="1.57"
      velocity="1.57" />
  </joint>
  <link
    name="thumb_prox_link">
    <inertial>
      <origin
        xyz="0.0037499 -0.035664 0.011815"
        rpy="0 0 0" />
      <mass
        value="0.016483" />
      <inertia
        ixx="2.5501E-06"
        ixy="1.5733E-08"
        ixz="6.6481E-11"
        iyy="8.1249E-07"
        iyz="-1.2956E-10"
        izz="2.3164E-06" />
    </inertial>
    <visual>
      <origin
        xyz="0 0 0"
        rpy="0 0 0" />
      <geometry>
        <mesh
          filename="../meshes/thumb_prox_link.STL" />
      </geometry>
      <material
        name="">
        <color
          rgba="0.25098 0.25098 0.25098 1" />
      </material>
    </visual>
    <collision>
      <origin
        xyz="0 0 0"
        rpy="0 0 0" />
      <geometry>
        <mesh
          filename="../meshes/thumb_prox_link.STL" />
      </geometry>
    </collision>
  </link>
  <joint
    name="thumb_prox_joint"
    type="revolute">
    <origin
      xyz="0.0118 0.00040455 0.013"
      rpy="-1.5708 0 1.5708" />
    <parent
      link="thumb_bsae_link" />
    <child
      link="thumb_prox_link" />
    <axis
      xyz="0 0 1" />
    <limit
      lower="-0.785"
      upper="0.785"
      effort="0.785"
      velocity="0.785" />
  </joint>
  <link
    name="thumb_dist_link">
    <inertial>
      <origin
        xyz="0.0052849 -0.019558 0.01179"
        rpy="0 0 0" />
      <mass
        value="0.0081945" />
      <inertia
        ixx="9.1275E-07"
        ixy="1.434E-08"
        ixz="-4.4169E-10"
        iyy="3.9971E-07"
        iyz="2.1995E-10"
        izz="7.6457E-07" />
    </inertial>
    <visual>
      <origin
        xyz="0 0 0"
        rpy="0 0 0" />
      <geometry>
        <mesh
          filename="../meshes/thumb_dist_link.STL" />
      </geometry>
      <material
        name="">
        <color
          rgba="0.25098 0.25098 0.25098 1" />
      </material>
    </visual>
    <collision>
      <origin
        xyz="0 0 0"
        rpy="0 0 0" />
      <geometry>
        <mesh
          filename="../meshes/thumb_dist_link.STL" />
      </geometry>
    </collision>
  </link>
  <joint
    name="thumb_dist_joint"
    type="revolute">
    <origin
      xyz="0 -0.0654 0"
      rpy="0 0 0" />
    <parent
      link="thumb_prox_link" />
    <child
      link="thumb_dist_link" />
    <axis
      xyz="0 0 1" />
    <limit
      lower="-0.785"
      upper="0.785"
      effort="0.785"
      velocity="0.785" />
  </joint>
  <link
    name="index_1_base_link">
    <inertial>
      <origin
        xyz="4.8718E-09 0.00065334 0.0041416"
        rpy="0 0 0" />
      <mass
        value="0.0059562" />
      <inertia
        ixx="5.7999E-07"
        ixy="-5.097E-14"
        ixz="-3.7324E-13"
        iyy="5.1954E-07"
        iyz="3.2343E-08"
        izz="2.414E-07" />
    </inertial>
    <visual>
      <origin
        xyz="0 0 0"
        rpy="0 0 0" />
      <geometry>
        <mesh
          filename="../meshes/index_1_base_link.STL" />
      </geometry>
      <material
        name="">
        <color
          rgba="1 1 1 1" />
      </material>
    </visual>
    <collision>
      <origin
        xyz="0 0 0"
        rpy="0 0 0" />
      <geometry>
        <mesh
          filename="../meshes/index_1_base_link.STL" />
      </geometry>
    </collision>
  </link>
  <joint
    name="index_1_base_joint"
    type="revolute">
    <origin
      xyz="-0.0275 0.03715 0.0923"
      rpy="0 0 0" />
    <parent
      link="base_link" />
    <child
      link="index_1_base_link" />
    <axis
      xyz="0 0 1" />
    <limit
      lower="0"
      upper="1.57"
      effort="1.57"
      velocity="1.57" />
  </joint>
  <link
    name="index_1_prox_link">
    <inertial>
      <origin
        xyz="-0.0037499 0.035664 -0.011785"
        rpy="0 0 0" />
      <mass
        value="0.016483" />
      <inertia
        ixx="2.5501E-06"
        ixy="1.5733E-08"
        ixz="-6.6481E-11"
        iyy="8.1249E-07"
        iyz="1.2956E-10"
        izz="2.3164E-06" />
    </inertial>
    <visual>
      <origin
        xyz="0 0 0"
        rpy="0 0 0" />
      <geometry>
        <mesh
          filename="../meshes/index_1_prox_link.STL" />
      </geometry>
      <material
        name="">
        <color
          rgba="0.25098 0.25098 0.25098 1" />
      </material>
    </visual>
    <collision>
      <origin
        xyz="0 0 0"
        rpy="0 0 0" />
      <geometry>
        <mesh
          filename="../meshes/index_1_prox_link.STL" />
      </geometry>
    </collision>
  </link>
  <joint
    name="index_1_prox_joint"
    type="revolute">
    <origin
      xyz="0.0118 0.0002 0.013"
      rpy="1.5708 0 1.5708" />
    <parent
      link="index_1_base_link" />
    <child
      link="index_1_prox_link" />
    <axis
      xyz="0 0 1" />
    <limit
      lower="-0.785"
      upper="0.785"
      effort="0.785"
      velocity="0.785" />
  </joint>
  <link
    name="index_1_dist_link">
    <inertial>
      <origin
        xyz="-0.00528489013229476 0.0195583162536312 -0.0118099653821271"
        rpy="0 0 0" />
      <mass
        value="0.00819453945657895" />
      <inertia
        ixx="9.12753911656529E-07"
        ixy="1.43398179339355E-08"
        ixz="4.4169251134486E-10"
        iyy="3.99707120995986E-07"
        iyz="-2.19949482824185E-10"
        izz="7.64569644592233E-07" />
    </inertial>
    <visual>
      <origin
        xyz="0 0 0"
        rpy="0 0 0" />
      <geometry>
        <mesh
          filename="../meshes/index_1_dist_link.STL" />
      </geometry>
      <material
        name="">
        <color
          rgba="0.250980392156863 0.250980392156863 0.250980392156863 1" />
      </material>
    </visual>
    <collision>
      <origin
        xyz="0 0 0"
        rpy="0 0 0" />
      <geometry>
        <mesh
          filename="../meshes/index_1_dist_link.STL" />
      </geometry>
    </collision>
  </link>
  <joint
    name="index_1_dist_joint"
    type="revolute">
    <origin
      xyz="0 0.0654 0"
      rpy="0 0 0" />
    <parent
      link="index_1_prox_link" />
    <child
      link="index_1_dist_link" />
    <axis
      xyz="0 0 1" />
    <limit
      lower="-0.785"
      upper="0.785"
      effort="0.785"
      velocity="0.785" />
  </joint>
  <link
    name="index_2_base_link">
    <inertial>
      <origin
        xyz="4.87180940728082E-09 -0.00065334316221427 -0.00414157472646259"
        rpy="0 0 0" />
      <mass
        value="0.00595623693303909" />
      <inertia
        ixx="5.79985838603613E-07"
        ixy="5.09698546600106E-14"
        ixz="3.73241412440236E-13"
        iyy="5.19541232611213E-07"
        iyz="3.23428747445384E-08"
        izz="2.41401688992226E-07" />
    </inertial>
    <visual>
      <origin
        xyz="0 0 0"
        rpy="0 0 0" />
      <geometry>
        <mesh
          filename="../meshes/index_2_base_link.STL" />
      </geometry>
      <material
        name="">
        <color
          rgba="1 1 1 1" />
      </material>
    </visual>
    <collision>
      <origin
        xyz="0 0 0"
        rpy="0 0 0" />
      <geometry>
        <mesh
          filename="../meshes/index_2_base_link.STL" />
      </geometry>
    </collision>
  </link>
  <joint
    name="index_2_base_joint"
    type="revolute">
    <origin
      xyz="0.0275 0.03715 0.0923"
      rpy="3.1416 0 0" />
    <parent
      link="base_link" />
    <child
      link="index_2_base_link" />
    <axis
      xyz="0 0 1" />
    <limit
      lower="0"
      upper="1.57"
      effort="1.57"
      velocity="1.57" />
  </joint>
  <link
    name="index_2_prox_link">
    <inertial>
      <origin
        xyz="-0.00374992138855147 0.0356637065583229 -0.0117854754155759"
        rpy="0 0 0" />
      <mass
        value="0.0164827087762703" />
      <inertia
        ixx="2.55005451913781E-06"
        ixy="1.57328821432116E-08"
        ixz="-6.64807107604902E-11"
        iyy="8.12494405412609E-07"
        iyz="1.29559002168546E-10"
        izz="2.31638757109714E-06" />
    </inertial>
    <visual>
      <origin
        xyz="0 0 0"
        rpy="0 0 0" />
      <geometry>
        <mesh
          filename="../meshes/index_2_prox_link.STL" />
      </geometry>
      <material
        name="">
        <color
          rgba="0.250980392156863 0.250980392156863 0.250980392156863 1" />
      </material>
    </visual>
    <collision>
      <origin
        xyz="0 0 0"
        rpy="0 0 0" />
      <geometry>
        <mesh
          filename="../meshes/index_2_prox_link.STL" />
      </geometry>
    </collision>
  </link>
  <joint
    name="index_2_prox_joint"
    type="revolute">
    <origin
      xyz="0.0118 -0.0002 -0.013"
      rpy="-1.5708 0 -1.5708" />
    <parent
      link="index_2_base_link" />
    <child
      link="index_2_prox_link" />
    <axis
      xyz="0 0 1" />
    <limit
      lower="-0.785"
      upper="0.785"
      effort="0.785"
      velocity="0.785" />
  </joint>
  <link
    name="index_2_dist_link">
    <inertial>
      <origin
        xyz="-0.00528489013229475 0.0195583162536312 -0.0118099653821271"
        rpy="0 0 0" />
      <mass
        value="0.00819453945657895" />
      <inertia
        ixx="9.12753911656529E-07"
        ixy="1.43398179339354E-08"
        ixz="4.41692511344808E-10"
        iyy="3.99707120995986E-07"
        iyz="-2.19949482823209E-10"
        izz="7.64569644592233E-07" />
    </inertial>
    <visual>
      <origin
        xyz="0 0 0"
        rpy="0 0 0" />
      <geometry>
        <mesh
          filename="../meshes/index_2_dist_link.STL" />
      </geometry>
      <material
        name="">
        <color
          rgba="0.250980392156863 0.250980392156863 0.250980392156863 1" />
      </material>
    </visual>
    <collision>
      <origin
        xyz="0 0 0"
        rpy="0 0 0" />
      <geometry>
        <mesh
          filename="../meshes/index_2_dist_link.STL" />
      </geometry>
    </collision>
  </link>
  <joint
    name="index_2_dist_joint"
    type="revolute">
    <origin
      xyz="0 0.0654 0"
      rpy="0 0 0" />
    <parent
      link="index_2_prox_link" />
    <child
      link="index_2_dist_link" />
    <axis
      xyz="0 0 1" />
    <limit
      lower="-0.785"
      upper="0.785"
      effort="0.785"
      velocity="0.785" />
  </joint>
</robot>