<?xml version="1.0"?>filename="../meshes/
<!-- This URDF was automatically created by SolidWorks to URDF Exporter! Originally created by Stephen Brawner (brawner@gmail.com) 
     Commit Version: 1.6.0-4-g7f85cfe  Build Version: 1.6.7995.38578
     For more information, please see http://wiki.ros.org/sw_urdf_exporter -->
<robot
  name="finray3f">
  <link
    name="base_link">
    <inertial>
      <origin
        xyz="6.9094E-05 -5.6139E-11 -0.054482"
        rpy="0 0 0" />
      <mass
        value="0.26864" />
      <inertia
        ixx="0.00035653"
        ixy="6.8574E-13"
        ixz="-9.7436E-07"
        iyy="0.00035023"
        iyz="5.4915E-13"
        izz="0.00024574" />
    </inertial>
    <visual>
      <origin
        xyz="0 0 0"
        rpy="0 0 0" />
      <geometry>
        <mesh
          filename="../meshes/base_link.STL" />
      </geometry>
      <material
        name="">
        <color
          rgba="1 1 1 1" />
      </material>
    </visual>
    <collision>
      <origin
        xyz="0 0 0"
        rpy="0 0 0" />
      <geometry>
        <mesh
          filename="../meshes/base_link.STL" />
      </geometry>
    </collision>
  </link>
  <link
    name="finger_1_link">
    <inertial>
      <origin
        xyz="-0.016251 0.033233 3.374E-20"
        rpy="0 0 0" />
      <mass
        value="0.039598" />
      <inertia
        ixx="4.5174E-05"
        ixy="-3.3076E-07"
        ixz="-2.0391E-21"
        iyy="7.2061E-06"
        iyz="-4.632E-21"
        izz="4.9186E-05" />
    </inertial>
    <visual>
      <origin
        xyz="0 0 0"
        rpy="0 0 0" />
      <geometry>
        <mesh
          filename="../meshes/finger_1_link.STL" />
      </geometry>
      <material
        name="">
        <color
          rgba="0.79216 0.81961 0.93333 1" />
      </material>
    </visual>
    <collision>
      <origin
        xyz="0 0 0"
        rpy="0 0 0" />
      <geometry>
        <mesh
          filename="../meshes/finger_1_link.STL" />
      </geometry>
    </collision>
  </link>
  <joint
    name="finger_1_joint"
    type="revolute">
    <origin
      xyz="0.056 0 -0.014"
      rpy="1.5708 0.2618 0" />
    <parent
      link="base_link" />
    <child
      link="finger_1_link" />
    <axis
      xyz="0 0 1" />
    <limit
      lower="0"
      upper="0.785"
      effort="0.785"
      velocity="0.785" />
  </joint>
  <link
    name="finger_2_link">
    <inertial>
      <origin
        xyz="-0.016251 0.033233 -1.7347E-17"
        rpy="0 0 0" />
      <mass
        value="0.039598" />
      <inertia
        ixx="4.5174E-05"
        ixy="-3.3076E-07"
        ixz="1.6941E-21"
        iyy="7.2061E-06"
        iyz="-1.7523E-20"
        izz="4.9186E-05" />
    </inertial>
    <visual>
      <origin
        xyz="0 0 0"
        rpy="0 0 0" />
      <geometry>
        <mesh
          filename="../meshes/finger_2_link.STL" />
      </geometry>
      <material
        name="">
        <color
          rgba="0.79216 0.81961 0.93333 1" />
      </material>
    </visual>
    <collision>
      <origin
        xyz="0 0 0"
        rpy="0 0 0" />
      <geometry>
        <mesh
          filename="../meshes/finger_2_link.STL" />
      </geometry>
    </collision>
  </link>
  <joint
    name="finger_2_joint"
    type="revolute">
    <origin
      xyz="-0.028 0.048497 -0.014"
      rpy="1.5708 0.2618 2.0944" />
    <parent
      link="base_link" />
    <child
      link="finger_2_link" />
    <axis
      xyz="0 0 1" />
    <limit
      lower="0"
      upper="0.785"
      effort="0.785"
      velocity="0.785" />
  </joint>
  <link
    name="finger_3_link">
    <inertial>
      <origin
        xyz="0 0 0"
        rpy="0 0 0" />
      <mass
        value="0" />
      <inertia
        ixx="0"
        ixy="0"
        ixz="0"
        iyy="0"
        iyz="0"
        izz="0" />
    </inertial>
    <visual>
      <origin
        xyz="0 0 0"
        rpy="0 0 0" />
      <geometry>
        <mesh
          filename="../meshes/finger_3_link.STL" />
      </geometry>
      <material
        name="">
        <color
          rgba="1 1 1 1" />
      </material>
    </visual>
    <collision>
      <origin
        xyz="0 0 0"
        rpy="0 0 0" />
      <geometry>
        <mesh
          filename="../meshes/finger_3_link.STL" />
      </geometry>
    </collision>
  </link>
  <joint
    name="finger_3_joint"
    type="revolute">
    <origin
      xyz="-0.028 -0.048497 -0.014"
      rpy="-1.5708 -0.2618 1.0472" />
    <parent
      link="base_link" />
    <child
      link="finger_3_link" />
    <axis
      xyz="0 0 1" />
    <limit
      lower="0"
      upper="0.785"
      effort="0.785"
      velocity="0.785" />
  </joint>
</robot>