<?xml version="1.0" encoding="utf-8"?>
<!-- This URDF was automatically created by SolidWorks to URDF Exporter! Originally created by Stephen Brawner (brawner@gmail.com) 
     Commit Version: 1.6.0-4-g7f85cfe  Build Version: 1.6.7995.38578
     For more information, please see http://wiki.ros.org/sw_urdf_exporter -->
<robot
  name="rochu_4f">
  <link
    name="base_link">
    <inertial>
      <origin
        xyz="9.252E-18 -5.9123E-19 -0.017289"
        rpy="0 0 0" />
      <mass
        value="0.10913" />
      <inertia
        ixx="6.1847E-05"
        ixy="1.5552E-20"
        ixz="4.23E-22"
        iyy="6.1847E-05"
        iyz="1.0454E-20"
        izz="0.00011456" />
    </inertial>
    <visual>
      <origin
        xyz="0 0 0"
        rpy="0 0 0" />
      <geometry>
        <mesh
          filename="../meshes/base_link.STL" />
      </geometry>
      <material
        name="">
        <color
          rgba="0.68627 0.68627 0.68627 1" />
      </material>
    </visual>
    <collision>
      <origin
        xyz="0 0 0"
        rpy="0 0 0" />
      <geometry>
        <mesh
          filename="../meshes/base_link.STL" />
      </geometry>
    </collision>
  </link>
  <link
    name="finger_1_link">
    <inertial>
      <origin
        xyz="0.010413 0.029604 2.9855E-08"
        rpy="0 0 0" />
      <mass
        value="0.034805" />
      <inertia
        ixx="2.9064E-05"
        ixy="8.9582E-07"
        ixz="-1.0727E-11"
        iyy="2.2306E-06"
        iyz="-7.7005E-10"
        izz="2.9547E-05" />
    </inertial>
    <visual>
      <origin
        xyz="0 0 0"
        rpy="0 0 0" />
      <geometry>
        <mesh
          filename="../meshes/finger_1_link.STL" />
      </geometry>
      <material
        name="">
        <color
          rgba="0 0 0 1" />
      </material>
    </visual>
    <collision>
      <origin
        xyz="0 0 0"
        rpy="0 0 0" />
      <geometry>
        <mesh
          filename="../meshes/finger_1_link.STL" />
      </geometry>
    </collision>
  </link>
  <joint
    name="finger_1_joint"
    type="revolute">
    <origin
      xyz="0.044 0 -0.03755"
      rpy="-1.5708 0 0" />
    <parent
      link="base_link" />
    <child
      link="finger_1_link" />
    <axis
      xyz="0 0 1" />
    <limit
      lower="-0.3725"
      upper="0.785"
      effort="0.785"
      velocity="0.785" />
  </joint>
  <link
    name="finger_2_link">
    <inertial>
      <origin
        xyz="0.010413 0.029604 2.9691E-08"
        rpy="0 0 0" />
      <mass
        value="0.034805" />
      <inertia
        ixx="2.9064E-05"
        ixy="8.9582E-07"
        ixz="-1.0751E-11"
        iyy="2.2306E-06"
        iyz="-7.7027E-10"
        izz="2.9547E-05" />
    </inertial>
    <visual>
      <origin
        xyz="0 0 0"
        rpy="0 0 0" />
      <geometry>
        <mesh
          filename="../meshes/finger_2_link.STL" />
      </geometry>
      <material
        name="">
        <color
          rgba="0 0 0 1" />
      </material>
    </visual>
    <collision>
      <origin
        xyz="0 0 0"
        rpy="0 0 0" />
      <geometry>
        <mesh
          filename="../meshes/finger_2_link.STL" />
      </geometry>
    </collision>
  </link>
  <joint
    name="finger_2_joint"
    type="revolute">
    <origin
      xyz="0 0.044 -0.03755"
      rpy="-1.5708 0 1.5708" />
    <parent
      link="base_link" />
    <child
      link="finger_2_link" />
    <axis
      xyz="0 0 1" />
    <limit
      lower="-0.3725"
      upper="0.785"
      effort="0.785"
      velocity="0.785" />
  </joint>
  <link
    name="finger_3_link">
    <inertial>
      <origin
        xyz="-0.010413 -0.029604 2.9855E-08"
        rpy="0 0 0" />
      <mass
        value="0.034805" />
      <inertia
        ixx="2.9064E-05"
        ixy="8.9582E-07"
        ixz="1.0727E-11"
        iyy="2.2306E-06"
        iyz="7.7005E-10"
        izz="2.9547E-05" />
    </inertial>
    <visual>
      <origin
        xyz="0 0 0"
        rpy="0 0 0" />
      <geometry>
        <mesh
          filename="../meshes/finger_3_link.STL" />
      </geometry>
      <material
        name="">
        <color
          rgba="0 0 0 1" />
      </material>
    </visual>
    <collision>
      <origin
        xyz="0 0 0"
        rpy="0 0 0" />
      <geometry>
        <mesh
          filename="../meshes/finger_3_link.STL" />
      </geometry>
    </collision>
  </link>
  <joint
    name="finger_3_joint"
    type="revolute">
    <origin
      xyz="-0.044 0 -0.03755"
      rpy="1.5708 0 0" />
    <parent
      link="base_link" />
    <child
      link="finger_3_link" />
    <axis
      xyz="0 0 1" />
    <limit
      lower="-0.3725"
      upper="0.785"
      effort="0.785"
      velocity="0.785" />
  </joint>
  <link
    name="finger_4_link">
    <inertial>
      <origin
        xyz="-0.010413 -0.029604 2.9855E-08"
        rpy="0 0 0" />
      <mass
        value="0.034805" />
      <inertia
        ixx="2.9064E-05"
        ixy="8.9582E-07"
        ixz="1.0727E-11"
        iyy="2.2306E-06"
        iyz="7.7005E-10"
        izz="2.9547E-05" />
    </inertial>
    <visual>
      <origin
        xyz="0 0 0"
        rpy="0 0 0" />
      <geometry>
        <mesh
          filename="../meshes/finger_4_link.STL" />
      </geometry>
      <material
        name="">
        <color
          rgba="0 0 0 1" />
      </material>
    </visual>
    <collision>
      <origin
        xyz="0 0 0"
        rpy="0 0 0" />
      <geometry>
        <mesh
          filename="../meshes/finger_4_link.STL" />
      </geometry>
    </collision>
  </link>
  <joint
    name="finger_4_joint"
    type="revolute">
    <origin
      xyz="0 -0.044 -0.03755"
      rpy="1.5708 0 1.5708" />
    <parent
      link="base_link" />
    <child
      link="finger_4_link" />
    <axis
      xyz="0 0 1" />
    <limit
      lower="-0.3725"
      upper="0.785"
      effort="0.785"
      velocity="0.785" />
  </joint>
</robot>